<?xml version="1.0" ?>
<!-- This file was generated by robot assembler -->
<robot name="FORTH"
       xmlns:xi="http://www.w3.org/2001/XInclude"
       xmlns:gazebo="http://playerstage.sourceforge.net/gazebo/xmlschema/#gz"
       xmlns:model="http://playerstage.sourceforge.net/gazebo/xmlschema/#model"
       xmlns:sensor="http://playerstage.sourceforge.net/gazebo/xmlschema/#sensor"
       xmlns:body="http://playerstage.sourceforge.net/gazebo/xmlschema/#body"
       xmlns:geom="http://playerstage.sourceforge.net/gazebo/xmlschema/#geom"
       xmlns:joint="http://playerstage.sourceforge.net/gazebo/xmlschema/#joint"
       xmlns:interface="http://playerstage.sourceforge.net/gazebo/xmlschema/#interface"
       xmlns:rendering="http://playerstage.sourceforge.net/gazebo/xmlschema/#rendering"
       xmlns:renderable="http://playerstage.sourceforge.net/gazebo/xmlschema/#renderable"
       xmlns:controller="http://playerstage.sourceforge.net/gazebo/xmlschema/#controller"
       xmlns:physics="http://playerstage.sourceforge.net/gazebo/xmlschema/#physics"
       xmlns:xacro="http://www.ros.org/wiki/xacro">
  <xacro:macro name="gazebo_link_reference" params="link_name mu1:=0.9 mu2:=0.9" >
    <gazebo reference="${link_name}">
      <mu1>${mu1}</mu1>
      <mu2>${mu2}</mu2>
      <kp>100000.0</kp>
      <kd>40.0</kd>
    </gazebo>
  </xacro:macro>
  <xacro:macro name="gazebo_transmission" params="joint_name" >
    <transmission name="${joint_name}_trans">
      <type>transmission_interface/SimpleTransmission</type>
      <joint name="${joint_name}">
        <hardwareInterface>hardware_interface/VelocityJointInterface</hardwareInterface>
      </joint>
      <actuator name="${joint_name}_motor">
        <hardwareInterface>hardware_interface/VelocityJointInterface</hardwareInterface>
        <mechanicalReduction>1</mechanicalReduction>
      </actuator>
    </transmission>
  </xacro:macro>

  <link name="world" />
  <xacro:gazebo_link_reference link_name="BASE" />
  <link name="BASE">
  <inertial>
     <mass value="0.1"/>
     <origin rpy="0 0 0" xyz="0.0 -0.012 0.0015"/>
     <inertia ixx="3.202708e-05" ixy="0.0" ixz="0.0" iyy="2.077708e-05" iyz="3.549874e-37" izz="2.478750e-05"/>
  </inertial>
  <visual>
     <origin xyz="0.000000 0.000000 0.000000" rpy="0.00000000 -0.00000000 0.00000000"/>
     <geometry>
     <mesh filename="file:///catkin_ws/src/robot_assembler/meshes/xm430_dynamixel.dae" scale="1.000000 1.000000 1.000000"/>
     </geometry>
  </visual>
  <collision>
     <origin xyz="0.000000 0.000000 0.000000" rpy="0.00000000 -0.00000000 0.00000000"/>
     <geometry>
     <mesh filename="file:///catkin_ws/src/robot_assembler/meshes/xm430_dynamixel.dae" scale="1.000000 1.000000 1.000000"/>
     </geometry>
  </collision>
  </link>
  <xacro:gazebo_link_reference link_name="LINK0" />
  <link name="LINK0">
  <inertial>
     <mass value="0.115"/>
     <origin rpy="0 0 0" xyz="-0.001304 0.04632 -0.019"/>
     <inertia ixx="4.539431e-05" ixy="7.395652e-07" ixz="-1.265155e-20" iyy="2.381893e-05" iyz="-5.254927e-21" izz="5.385323e-05"/>
  </inertial>
  <visual>
     <origin xyz="0.000000 0.000000 -0.019000" rpy="0.00000000 1.57079633 0.00000000"/>
     <geometry>
     <mesh filename="file:///catkin_ws/src/robot_assembler/meshes/fr12_h101.dae" scale="1.000000 1.000000 1.000000"/>
     </geometry>
  </visual>
  <collision>
     <origin xyz="0.000000 0.000000 -0.019000" rpy="0.00000000 1.57079633 0.00000000"/>
     <geometry>
     <mesh filename="file:///catkin_ws/src/robot_assembler/meshes/fr12_h101.dae" scale="1.000000 1.000000 1.000000"/>
     </geometry>
  </collision>
  <visual>
     <origin xyz="-0.000000 0.063250 -0.019000" rpy="-3.14159265 -1.57079633 -3.14159265"/>
     <geometry>
     <mesh filename="file:///catkin_ws/src/robot_assembler/meshes/xm430_dynamixel.dae" scale="1.000000 1.000000 1.000000"/>
     </geometry>
  </visual>
  <collision>
     <origin xyz="-0.000000 0.063250 -0.019000" rpy="-3.14159265 -1.57079633 -3.14159265"/>
     <geometry>
     <mesh filename="file:///catkin_ws/src/robot_assembler/meshes/xm430_dynamixel.dae" scale="1.000000 1.000000 1.000000"/>
     </geometry>
  </collision>
  </link>
  <xacro:gazebo_link_reference link_name="LINK1" />
  <link name="LINK1">
  <inertial>
     <mass value="0.115"/>
     <origin rpy="0 0 0" xyz="0.001304 0.04632 -0.019"/>
     <inertia ixx="4.539431e-05" ixy="-7.395652e-07" ixz="-3.354039e-21" iyy="2.381893e-05" iyz="-7.228096e-21" izz="5.385323e-05"/>
  </inertial>
  <visual>
     <origin xyz="-0.000000 0.000000 -0.019000" rpy="0.00000000 1.57079633 0.00000000"/>
     <geometry>
     <mesh filename="file:///catkin_ws/src/robot_assembler/meshes/fr12_h101.dae" scale="1.000000 1.000000 1.000000"/>
     </geometry>
  </visual>
  <collision>
     <origin xyz="-0.000000 0.000000 -0.019000" rpy="0.00000000 1.57079633 0.00000000"/>
     <geometry>
     <mesh filename="file:///catkin_ws/src/robot_assembler/meshes/fr12_h101.dae" scale="1.000000 1.000000 1.000000"/>
     </geometry>
  </collision>
  <visual>
     <origin xyz="-0.000000 0.063250 -0.019000" rpy="0.64065233 1.57079633 0.64065233"/>
     <geometry>
     <mesh filename="file:///catkin_ws/src/robot_assembler/meshes/xm430_dynamixel.dae" scale="1.000000 1.000000 1.000000"/>
     </geometry>
  </visual>
  <collision>
     <origin xyz="-0.000000 0.063250 -0.019000" rpy="0.64065233 1.57079633 0.64065233"/>
     <geometry>
     <mesh filename="file:///catkin_ws/src/robot_assembler/meshes/xm430_dynamixel.dae" scale="1.000000 1.000000 1.000000"/>
     </geometry>
  </collision>
  </link>
  <xacro:gazebo_link_reference link_name="LINK2" />
  <link name="LINK2">
  <inertial>
     <mass value="0.115"/>
     <origin rpy="0 0 0" xyz="-0.001304 0.04632 -0.019"/>
     <inertia ixx="4.539431e-05" ixy="7.395652e-07" ixz="-7.774690e-21" iyy="2.381893e-05" iyz="2.771637e-21" izz="5.385323e-05"/>
  </inertial>
  <visual>
     <origin xyz="0.000000 0.000000 -0.019000" rpy="-0.00000000 1.57079633 -0.00000000"/>
     <geometry>
     <mesh filename="file:///catkin_ws/src/robot_assembler/meshes/fr12_h101.dae" scale="1.000000 1.000000 1.000000"/>
     </geometry>
  </visual>
  <collision>
     <origin xyz="0.000000 0.000000 -0.019000" rpy="-0.00000000 1.57079633 -0.00000000"/>
     <geometry>
     <mesh filename="file:///catkin_ws/src/robot_assembler/meshes/fr12_h101.dae" scale="1.000000 1.000000 1.000000"/>
     </geometry>
  </collision>
  <visual>
     <origin xyz="-0.000000 0.063250 -0.019000" rpy="3.05171446 -1.57079633 -3.05171446"/>
     <geometry>
     <mesh filename="file:///catkin_ws/src/robot_assembler/meshes/xm430_dynamixel.dae" scale="1.000000 1.000000 1.000000"/>
     </geometry>
  </visual>
  <collision>
     <origin xyz="-0.000000 0.063250 -0.019000" rpy="3.05171446 -1.57079633 -3.05171446"/>
     <geometry>
     <mesh filename="file:///catkin_ws/src/robot_assembler/meshes/xm430_dynamixel.dae" scale="1.000000 1.000000 1.000000"/>
     </geometry>
  </collision>
  </link>
  <xacro:gazebo_link_reference link_name="LINK3" />
  <link name="LINK3">
  <inertial>
     <mass value="0.115"/>
     <origin rpy="0 0 0" xyz="0.001304 0.04632 -0.019"/>
     <inertia ixx="4.539431e-05" ixy="-7.395652e-07" ixz="-1.746529e-21" iyy="2.381893e-05" iyz="-7.054376e-21" izz="5.385323e-05"/>
  </inertial>
  <visual>
     <origin xyz="-0.000000 0.000000 -0.019000" rpy="-0.00000000 1.57079633 -0.00000000"/>
     <geometry>
     <mesh filename="file:///catkin_ws/src/robot_assembler/meshes/fr12_h101.dae" scale="1.000000 1.000000 1.000000"/>
     </geometry>
  </visual>
  <collision>
     <origin xyz="-0.000000 0.000000 -0.019000" rpy="-0.00000000 1.57079633 -0.00000000"/>
     <geometry>
     <mesh filename="file:///catkin_ws/src/robot_assembler/meshes/fr12_h101.dae" scale="1.000000 1.000000 1.000000"/>
     </geometry>
  </collision>
  <visual>
     <origin xyz="-0.000000 0.063250 -0.019000" rpy="0.95776124 1.57079633 0.95776124"/>
     <geometry>
     <mesh filename="file:///catkin_ws/src/robot_assembler/meshes/xm430_dynamixel.dae" scale="1.000000 1.000000 1.000000"/>
     </geometry>
  </visual>
  <collision>
     <origin xyz="-0.000000 0.063250 -0.019000" rpy="0.95776124 1.57079633 0.95776124"/>
     <geometry>
     <mesh filename="file:///catkin_ws/src/robot_assembler/meshes/xm430_dynamixel.dae" scale="1.000000 1.000000 1.000000"/>
     </geometry>
  </collision>
  </link>
  <xacro:gazebo_link_reference link_name="LINK4" />
  <link name="LINK4">
  <inertial>
     <mass value="0.04"/>
     <origin rpy="0 0 0" xyz="-6.713348e-18 0.023794 -0.01525"/>
     <inertia ixx="1.240843e-05" ixy="-1.619091e-20" ixz="-7.228043e-21" iyy="2.418333e-05" iyz="-9.309375e-07" izz="1.909427e-05"/>
  </inertial>
  <visual>
     <origin xyz="-0.000000 0.000000 -0.019000" rpy="-0.00000000 1.57079633 0.00000000"/>
     <geometry>
     <mesh filename="file:///catkin_ws/src/robot_assembler/meshes/fr12_h101.dae" scale="1.000000 1.000000 1.000000"/>
     </geometry>
  </visual>
  <collision>
     <origin xyz="-0.000000 0.000000 -0.019000" rpy="-0.00000000 1.57079633 0.00000000"/>
     <geometry>
     <mesh filename="file:///catkin_ws/src/robot_assembler/meshes/fr12_h101.dae" scale="1.000000 1.000000 1.000000"/>
     </geometry>
  </collision>
  <visual>
     <origin xyz="-0.000000 0.032000 -0.013000" rpy="-1.57079633 0.00000000 -3.14159265"/>
     <geometry>
     <mesh filename="file:///catkin_ws/src/robot_assembler/meshes/foot-plate.dae" scale="1.000000 1.000000 1.000000"/>
     </geometry>
  </visual>
  <collision>
     <origin xyz="-0.000000 0.032000 -0.013000" rpy="-1.57079633 0.00000000 -3.14159265"/>
     <geometry>
     <mesh filename="file:///catkin_ws/src/robot_assembler/meshes/foot-plate.dae" scale="1.000000 1.000000 1.000000"/>
     </geometry>
  </collision>
  </link>
  <link name="LINKCAM"/>
  <link name="LINKCAMOPT"/>

  <gazebo reference="LINKCAM">
     <sensor type="multicamera" name="stereo_camera">
        <update_rate>30.0</update_rate>
        <camera name="left">
           <horizontal_fov>1.3962634</horizontal_fov>
           <image>
              <width>800</width>
              <height>600</height>
              <format>R8G8B8</format>
           </image>
           <clip>
              <near>0.02</near>
              <far>300</far>
           </clip>
           <noise>
              <type>gaussian</type>
              <mean>0.0</mean>
              <stddev>0.007</stddev>
           </noise>
        </camera>
        <camera name="right">
           <pose>0 -0.2 0 0 0 0</pose>
           <horizontal_fov>1.3962634</horizontal_fov>
           <image>
              <width>800</width>
              <height>600</height>
              <format>R8G8B8</format>
           </image>
           <clip>
              <near>0.02</near>
              <far>300</far>
           </clip>
           <noise>
              <type>gaussian</type>
              <mean>0.0</mean>
              <stddev>0.007</stddev>
           </noise>
        </camera>
        <plugin name="stereo_camera_controller" filename="libgazebo_ros_multicamera.so">
           <alwaysOn>true</alwaysOn>
           <updateRate>0.0</updateRate>
           <cameraName>stereo_camera</cameraName>
           <imageTopicName>image_raw</imageTopicName>
           <cameraInfoTopicName>camera_info</cameraInfoTopicName>
           <frameName>LINKCAMOPT</frameName>
           <hackBaseline>0.07</hackBaseline>
           <distortionK1>0.0</distortionK1>
           <distortionK2>0.0</distortionK2>
           <distortionK3>0.0</distortionK3>
           <distortionT1>0.0</distortionT1>
           <distortionT2>0.0</distortionT2>
        </plugin>
     </sensor>
  </gazebo>
  <joint name="WORLD2BASE" type="fixed">
      <parent link="world"/>
      <child link="BASE"/>
      <origin xyz="0 0 -0.265" rpy="0 0 0"/>
  </joint>
  <xacro:gazebo_transmission joint_name="JOINT0" />
  <joint name="JOINT0" type="revolute">
     <parent link="BASE"/>
     <child link="LINK0"/>
     <origin xyz="0.000000 0.000000 0.019000" rpy="0.00000000 -0.00000000 0.00000000"/>
     <axis xyz="0 0 1"/>
     <limit effort="200" lower="-3.14159" upper="3.14159" velocity="40"/>
  </joint>
  <xacro:gazebo_transmission joint_name="JOINT1" />
  <joint name="JOINT1" type="revolute">
     <parent link="LINK0"/>
     <child link="LINK1"/>
     <origin xyz="-0.019000 0.063250 -0.019000" rpy="-3.14159265 -1.57079633 -3.14159265"/>
     <axis xyz="0 0 1"/>
     <limit effort="200" lower="-3.14159" upper="3.14159" velocity="40"/>
  </joint>
  <xacro:gazebo_transmission joint_name="JOINT2" />
  <joint name="JOINT2" type="revolute">
     <parent link="LINK1"/>
     <child link="LINK2"/>
     <origin xyz="0.019000 0.063250 -0.019000" rpy="0.64065233 1.57079633 0.64065233"/>
     <axis xyz="0 0 1"/>
     <limit effort="200" lower="-3.14159" upper="3.14159" velocity="40"/>
  </joint>
  <xacro:gazebo_transmission joint_name="JOINT3" />
  <joint name="JOINT3" type="revolute">
     <parent link="LINK2"/>
     <child link="LINK3"/>
     <origin xyz="-0.019000 0.063250 -0.019000" rpy="3.05171446 -1.57079633 -3.05171446"/>
     <axis xyz="0 0 1"/>
     <limit effort="200" lower="-3.14159" upper="3.14159" velocity="40"/>
  </joint>
  <xacro:gazebo_transmission joint_name="JOINT4" />
  <joint name="JOINT4" type="revolute">
     <parent link="LINK3"/>
     <child link="LINK4"/>
     <origin xyz="0.019000 0.063250 -0.019000" rpy="0.95776124 1.57079633 0.95776124"/>
     <axis xyz="0 0 1"/>
     <limit effort="200" lower="-3.14159" upper="3.14159" velocity="40"/>
  </joint>
  <joint name="JOINTCAM" type="fixed">
      <parent link="LINK4"/>
      <child link="LINKCAM"/>
      <origin xyz="0 0.03 0" rpy="0 0 1.5708"/>
  </joint>
  <joint name="JOINTCAMOPT" type="fixed">
      <parent link="LINKCAM"/>
      <child link="LINKCAMOPT"/>
      <origin xyz="0 0 0" rpy="-1.5708 0 -1.5708"/>
  </joint>

  <!-- Gazebo plugin for ROS Control -->
  <gazebo>
    <plugin name="gazebo_ros_control" filename="libgazebo_ros_control.so">
      <!--robotNamespace>/</robotNamespace-->
      <legacyModeNS>false</legacyModeNS>
      <robotSimType>gazebo_ros_control/DefaultRobotHWSim</robotSimType>
    </plugin>
  </gazebo>
</robot>
