<?xml version="1.0" ?>
<!-- This file was generated by robot assembler -->
<robot name="MHATTORI"
       xmlns:xi="http://www.w3.org/2001/XInclude"
       xmlns:gazebo="http://playerstage.sourceforge.net/gazebo/xmlschema/#gz"
       xmlns:model="http://playerstage.sourceforge.net/gazebo/xmlschema/#model"
       xmlns:sensor="http://playerstage.sourceforge.net/gazebo/xmlschema/#sensor"
       xmlns:body="http://playerstage.sourceforge.net/gazebo/xmlschema/#body"
       xmlns:geom="http://playerstage.sourceforge.net/gazebo/xmlschema/#geom"
       xmlns:joint="http://playerstage.sourceforge.net/gazebo/xmlschema/#joint"
       xmlns:interface="http://playerstage.sourceforge.net/gazebo/xmlschema/#interface"
       xmlns:rendering="http://playerstage.sourceforge.net/gazebo/xmlschema/#rendering"
       xmlns:renderable="http://playerstage.sourceforge.net/gazebo/xmlschema/#renderable"
       xmlns:controller="http://playerstage.sourceforge.net/gazebo/xmlschema/#controller"
       xmlns:physics="http://playerstage.sourceforge.net/gazebo/xmlschema/#physics"
       xmlns:xacro="http://www.ros.org/wiki/xacro">
  <xacro:macro name="gazebo_link_reference" params="link_name mu1:=0.9 mu2:=0.9" >
    <gazebo reference="${link_name}">
      <mu1>${mu1}</mu1>
      <mu2>${mu2}</mu2>
    </gazebo>
  </xacro:macro>
  <xacro:macro name="gazebo_transmission" params="joint_name" >
    <transmission name="${joint_name}_trans">
      <type>transmission_interface/SimpleTransmission</type>
      <joint name="${joint_name}">
        <hardwareInterface>hardware_interface/PositionJointInterface</hardwareInterface>
      </joint>
      <actuator name="${joint_name}_motor">
        <hardwareInterface>hardware_interface/PositionJointInterface</hardwareInterface>
        <mechanicalReduction>1</mechanicalReduction>
      </actuator>
    </transmission>
  </xacro:macro>

  <xacro:gazebo_link_reference link_name="BASE" />
  <link name="BASE">
  <inertial>
     <mass value="0.1"/>
     <origin rpy="0 0 0" xyz="0.0 -0.012 0.0015"/>
     <inertia ixx="3.202708e-05" ixy="0.0" ixz="0.0" iyy="2.077708e-05" iyz="3.549874e-37" izz="2.478750e-05"/>
  </inertial>
  <visual>
     <origin xyz="0.000000 0.000000 0.000000" rpy="0.00000000 -0.00000000 0.00000000"/>
     <geometry>
     <mesh filename="file:///catkin_ws/src/robot_assembler/meshes/xm430_dynamixel.dae" scale="1.000000 1.000000 1.000000"/>
     </geometry>
  </visual>
  <collision>
     <origin xyz="0.000000 0.000000 0.000000" rpy="0.00000000 -0.00000000 0.00000000"/>
     <geometry>
     <mesh filename="file:///catkin_ws/src/robot_assembler/meshes/xm430_dynamixel.dae" scale="1.000000 1.000000 1.000000"/>
     </geometry>
  </collision>
  </link>
  <xacro:gazebo_link_reference link_name="LINK0" />
  <link name="LINK0">
  <inertial>
     <mass value="0.115"/>
     <origin rpy="0 0 0" xyz="-0.001304 0.04632 -0.019"/>
     <inertia ixx="4.539431e-05" ixy="7.395652e-07" ixz="-1.479995e-20" iyy="2.381893e-05" iyz="-2.855614e-21" izz="5.385323e-05"/>
  </inertial>
  <visual>
     <origin xyz="0.000000 0.000000 -0.019000" rpy="0.00000000 1.57079633 0.00000000"/>
     <geometry>
     <mesh filename="file:///catkin_ws/src/robot_assembler/meshes/fr12_h101.dae" scale="1.000000 1.000000 1.000000"/>
     </geometry>
  </visual>
  <collision>
     <origin xyz="0.000000 0.000000 -0.019000" rpy="0.00000000 1.57079633 0.00000000"/>
     <geometry>
     <mesh filename="file:///catkin_ws/src/robot_assembler/meshes/fr12_h101.dae" scale="1.000000 1.000000 1.000000"/>
     </geometry>
  </collision>
  <visual>
     <origin xyz="-0.000000 0.063250 -0.019000" rpy="3.09385147 -1.57079633 -3.09385147"/>
     <geometry>
     <mesh filename="file:///catkin_ws/src/robot_assembler/meshes/xm430_dynamixel.dae" scale="1.000000 1.000000 1.000000"/>
     </geometry>
  </visual>
  <collision>
     <origin xyz="-0.000000 0.063250 -0.019000" rpy="3.09385147 -1.57079633 -3.09385147"/>
     <geometry>
     <mesh filename="file:///catkin_ws/src/robot_assembler/meshes/xm430_dynamixel.dae" scale="1.000000 1.000000 1.000000"/>
     </geometry>
  </collision>
  </link>
  <xacro:gazebo_link_reference link_name="LINK1" />
  <link name="LINK1">
  <inertial>
     <mass value="0.115"/>
     <origin rpy="0 0 0" xyz="-0.001304 0.04632 -0.019"/>
     <inertia ixx="4.539431e-05" ixy="7.395652e-07" ixz="-1.004694e-20" iyy="2.381893e-05" iyz="-3.062429e-21" izz="5.385323e-05"/>
  </inertial>
  <visual>
     <origin xyz="-0.000000 0.000000 -0.019000" rpy="0.00000000 1.57079633 0.00000000"/>
     <geometry>
     <mesh filename="file:///catkin_ws/src/robot_assembler/meshes/fr12_h101.dae" scale="1.000000 1.000000 1.000000"/>
     </geometry>
  </visual>
  <collision>
     <origin xyz="-0.000000 0.000000 -0.019000" rpy="0.00000000 1.57079633 0.00000000"/>
     <geometry>
     <mesh filename="file:///catkin_ws/src/robot_assembler/meshes/fr12_h101.dae" scale="1.000000 1.000000 1.000000"/>
     </geometry>
  </collision>
  <visual>
     <origin xyz="-0.000000 0.063250 -0.019000" rpy="2.94789959 -1.57079633 -2.94789959"/>
     <geometry>
     <mesh filename="file:///catkin_ws/src/robot_assembler/meshes/xm430_dynamixel.dae" scale="1.000000 1.000000 1.000000"/>
     </geometry>
  </visual>
  <collision>
     <origin xyz="-0.000000 0.063250 -0.019000" rpy="2.94789959 -1.57079633 -2.94789959"/>
     <geometry>
     <mesh filename="file:///catkin_ws/src/robot_assembler/meshes/xm430_dynamixel.dae" scale="1.000000 1.000000 1.000000"/>
     </geometry>
  </collision>
  </link>
  <xacro:gazebo_link_reference link_name="LINK2" />
  <link name="LINK2">
  <inertial>
     <mass value="0.115"/>
     <origin rpy="0 0 0" xyz="-0.001304 0.04632 -0.019"/>
     <inertia ixx="4.539431e-05" ixy="7.395652e-07" ixz="-1.707220e-20" iyy="2.381893e-05" iyz="-1.104828e-20" izz="5.385323e-05"/>
  </inertial>
  <visual>
     <origin xyz="-0.000000 0.000000 -0.019000" rpy="-0.00000000 1.57079633 -0.00000000"/>
     <geometry>
     <mesh filename="file:///catkin_ws/src/robot_assembler/meshes/fr12_h101.dae" scale="1.000000 1.000000 1.000000"/>
     </geometry>
  </visual>
  <collision>
     <origin xyz="-0.000000 0.000000 -0.019000" rpy="-0.00000000 1.57079633 -0.00000000"/>
     <geometry>
     <mesh filename="file:///catkin_ws/src/robot_assembler/meshes/fr12_h101.dae" scale="1.000000 1.000000 1.000000"/>
     </geometry>
  </collision>
  <visual>
     <origin xyz="-0.000000 0.063250 -0.019000" rpy="2.92911029 -1.57079633 -2.92911029"/>
     <geometry>
     <mesh filename="file:///catkin_ws/src/robot_assembler/meshes/xm430_dynamixel.dae" scale="1.000000 1.000000 1.000000"/>
     </geometry>
  </visual>
  <collision>
     <origin xyz="-0.000000 0.063250 -0.019000" rpy="2.92911029 -1.57079633 -2.92911029"/>
     <geometry>
     <mesh filename="file:///catkin_ws/src/robot_assembler/meshes/xm430_dynamixel.dae" scale="1.000000 1.000000 1.000000"/>
     </geometry>
  </collision>
  </link>
  <xacro:gazebo_link_reference link_name="LINK3" />
  <link name="LINK3">
  <inertial>
     <mass value="0.04"/>
     <origin rpy="0 0 0" xyz="7.780962e-18 0.023794 -0.02275"/>
     <inertia ixx="1.240843e-05" ixy="-2.975735e-21" ixz="-8.458592e-21" iyy="2.418333e-05" iyz="9.309375e-07" izz="1.909427e-05"/>
  </inertial>
  <visual>
     <origin xyz="0.000000 0.000000 -0.019000" rpy="0.00000000 1.57079633 0.00000000"/>
     <geometry>
     <mesh filename="file:///catkin_ws/src/robot_assembler/meshes/fr12_h101.dae" scale="1.000000 1.000000 1.000000"/>
     </geometry>
  </visual>
  <collision>
     <origin xyz="0.000000 0.000000 -0.019000" rpy="0.00000000 1.57079633 0.00000000"/>
     <geometry>
     <mesh filename="file:///catkin_ws/src/robot_assembler/meshes/fr12_h101.dae" scale="1.000000 1.000000 1.000000"/>
     </geometry>
  </collision>
  <visual>
     <origin xyz="0.000000 0.032000 -0.025000" rpy="1.57079633 -0.00000000 0.00000000"/>
     <geometry>
     <mesh filename="file:///catkin_ws/src/robot_assembler/meshes/foot-plate.dae" scale="1.000000 1.000000 1.000000"/>
     </geometry>
  </visual>
  <collision>
     <origin xyz="0.000000 0.032000 -0.025000" rpy="1.57079633 -0.00000000 0.00000000"/>
     <geometry>
     <mesh filename="file:///catkin_ws/src/robot_assembler/meshes/foot-plate.dae" scale="1.000000 1.000000 1.000000"/>
     </geometry>
  </collision>
  </link>
  <xacro:gazebo_transmission joint_name="JOINT0" />
  <joint name="JOINT0" type="revolute">
     <parent link="BASE"/>
     <child link="LINK0"/>
     <origin xyz="0.000000 0.000000 0.019000" rpy="0.00000000 -0.00000000 0.00000000"/>
     <axis xyz="0 0 1"/>
     <limit effort="200" lower="-3.14159" upper="3.14159" velocity="40"/>
  </joint>
  <xacro:gazebo_transmission joint_name="JOINT1" />
  <joint name="JOINT1" type="revolute">
     <parent link="LINK0"/>
     <child link="LINK1"/>
     <origin xyz="-0.019000 0.063250 -0.019000" rpy="3.09385147 -1.57079633 -3.09385147"/>
     <axis xyz="0 0 1"/>
     <limit effort="200" lower="-3.14159" upper="3.14159" velocity="40"/>
  </joint>
  <xacro:gazebo_transmission joint_name="JOINT2" />
  <joint name="JOINT2" type="revolute">
     <parent link="LINK1"/>
     <child link="LINK2"/>
     <origin xyz="-0.019000 0.063250 -0.019000" rpy="2.94789959 -1.57079633 -2.94789959"/>
     <axis xyz="0 0 1"/>
     <limit effort="200" lower="-3.14159" upper="3.14159" velocity="40"/>
  </joint>
  <xacro:gazebo_transmission joint_name="JOINT3" />
  <joint name="JOINT3" type="revolute">
     <parent link="LINK2"/>
     <child link="LINK3"/>
     <origin xyz="-0.019000 0.063250 -0.019000" rpy="2.92911029 -1.57079633 -2.92911029"/>
     <axis xyz="0 0 1"/>
     <limit effort="200" lower="-3.14159" upper="3.14159" velocity="40"/>
  </joint>

  <!-- Gazebo plugin for ROS Control -->
  <gazebo>
    <plugin name="gazebo_ros_control" filename="libgazebo_ros_control.so">
      <robotNamespace>/</robotNamespace>
      <robotSimType>gazebo_ros_control/DefaultRobotHWSim</robotSimType>
    </plugin>
  </gazebo>
</robot>
